Already up to date.
rm -rf logs/extract/*
rm -rf logs/parse/*
rm -rf logs/tests/*
rm -rf logs/update/*
rm -f logs/full_extract.txt
rm -f logs/check_validation.txt
rm -f logs/check_empty_resource.txt
rm -f logs/ingest.txt
rm -f logs/build.txt
rm -f logs/create.txt
rm -rf data/raw/*
rm -f datapackage.json
rm -rf build_datasets
rm -rf reports.html
make: Nothing to be done for 'parse'.
# python scripts/python/full-extract.py
python scripts/python/extract_csv_evento_etl_carga.py 2> logs/evento_etl_carga.txt
dtamg-py etl-make full-extract 2> logs/full_extract.txt
rsync --itemize-changes --checksum data/raw/* data/staging/ 2> logs/ingest.txt
>fcsT...... dm_acao.csv
>fcsT...... dm_alinea_rec.csv
gzip -n < data/staging/dm_alinea_rec.csv > data/dm_alinea_rec.csv.gz
gzip -n < data/staging/dm_acao.csv > data/dm_acao.csv.gz
dtamg-py etl-make validate -r dm_alinea_rec > logs/validate/dm_alinea_rec.json
dtamg-py etl-make validate -r dm_acao > logs/validate/dm_acao.json
dtamg-py etl-make build-datapackage
Rscript --verbose -e "testthat::test_file('tests/testthat/test_dm_contratado.R', stop_on_failure=TRUE)" 2> logs/tests/test_dm_contratado.Rout

══ Testing test_dm_contratado.R ════════════════════════════════════════════════
[ FAIL 0 | WARN 0 | SKIP 0 | PASS 0 ][ FAIL 0 | WARN 0 | SKIP 0 | PASS 0 ][ FAIL 0 | WARN 0 | SKIP 0 | PASS 1 ][ FAIL 0 | WARN 0 | SKIP 0 | PASS 2 ] Done!
Rscript --verbose -e "testthat::test_file('tests/testthat/test_dm_favorecido.R', stop_on_failure=TRUE)" 2> logs/tests/test_dm_favorecido.Rout

══ Testing test_dm_favorecido.R ════════════════════════════════════════════════
[ FAIL 0 | WARN 0 | SKIP 0 | PASS 0 ][ FAIL 0 | WARN 0 | SKIP 0 | PASS 0 ][ FAIL 0 | WARN 0 | SKIP 0 | PASS 1 ][ FAIL 0 | WARN 0 | SKIP 0 | PASS 2 ][ FAIL 1 | WARN 0 | SKIP 0 | PASS 2 ][ FAIL 1 | WARN 1 | SKIP 0 | PASS 2 ][ FAIL 1 | WARN 1 | SKIP 0 | PASS 3 ][ FAIL 1 | WARN 1 | SKIP 0 | PASS 4 ][ FAIL 1 | WARN 1 | SKIP 0 | PASS 5 ][ FAIL 1 | WARN 1 | SKIP 0 | PASS 6 ]

── Error (test_dm_favorecido.R:33:3): Anonimização prêmios lotéricos ───────────
Error in `bmerge(i, x, leftcols, rightcols, roll, rollends, nomatch, mult, 
    ops, verbose = verbose)`: Incompatible join types: x.id_unidade_orc (logical) and i.id_unidade_orc (integer)
Backtrace:
 1. base::unlist(map(2002:2022, get_id_favorecido_premios_lotericos)) test_dm_favorecido.R:33:2
 2. purrr::map(2002:2022, get_id_favorecido_premios_lotericos)
 3. .f(.x[[i]], ...)
 5. data.table:::`[.data.table`(dm_unidade_orc, ft_despesa, on = "id_unidade_orc") test_dm_favorecido.R:24:4
 6. data.table:::bmerge(...)

── Warning (test_dm_favorecido.R:51:3): Anonimização hanseniase 2021 ───────────
Python '/work_dir/python' was requested but '/usr/local/bin/python' was loaded instead (see reticulate::py_config() for more information)
Backtrace:
  1. dtamg::flatten_resource(...) test_dm_favorecido.R:51:2
  3. reticulate:::`$.python.builtin.module`(frictionless, "Package")
  4. reticulate:::py_resolve_module_proxy(x)
  9. reticulate::import(module)
 10. reticulate:::ensure_python_initialized(required_module = module)
 11. reticulate:::initialize_python(required_module, use_environment)
 12. (function() {...

[ FAIL 1 | WARN 1 | SKIP 0 | PASS 6 ]
