2022-09-01T00:00:11+0000 INFO  [dtamg_py.utils] Extraindo recurso dm_poder...
Traceback (most recent call last):
  File "/usr/local/bin/dtamg-py", line 8, in <module>
    sys.exit(cli())
  File "/usr/local/lib/python3.9/site-packages/click/core.py", line 1130, in __call__
    return self.main(*args, **kwargs)
  File "/usr/local/lib/python3.9/site-packages/click/core.py", line 1055, in main
    rv = self.invoke(ctx)
  File "/usr/local/lib/python3.9/site-packages/click/core.py", line 1657, in invoke
    return _process_result(sub_ctx.command.invoke(sub_ctx))
  File "/usr/local/lib/python3.9/site-packages/click/core.py", line 1657, in invoke
    return _process_result(sub_ctx.command.invoke(sub_ctx))
  File "/usr/local/lib/python3.9/site-packages/click/core.py", line 1404, in invoke
    return ctx.invoke(self.callback, **ctx.params)
  File "/usr/local/lib/python3.9/site-packages/click/core.py", line 760, in invoke
    return __callback(*args, **kwargs)
  File "/usr/local/lib/python3.9/site-packages/dtamg_py/full_extract.py", line 10, in full_extract_cli
    full_extract()
  File "/usr/local/lib/python3.9/site-packages/dtamg_py/utils.py", line 76, in full_extract
    extract_resources(dp.resources)
  File "/usr/local/lib/python3.9/site-packages/dtamg_py/utils.py", line 41, in extract_resources
    extract_csv(connection, resource)
  File "/usr/local/lib/python3.9/site-packages/dtamg_py/utils.py", line 67, in extract_csv
    with open(f'data/raw/{resource.name}.csv', "w", encoding='utf-8-sig', newline='') as fp:
FileNotFoundError: [Errno 2] No such file or directory: 'data/raw/dm_poder.csv'
